Workbook

Sheet Result
B2: TPA Web Score
B6: =Master!D41 -> 64.62754

Sheet Master
B2: TPA Web Design and Technology Generation 25-1 SurVace
B7: Assistant | D7: KN
B8: AI Case Variation | D8: {=_xlfn._xlws.FILTER('AI Groups'!$B$2:$G$2,_xlfn.BYCOL('AI Groups'!$B$3:$G$8=UPPER(Master!$D$7),_xlfn.LAMBDA(_xlpm.x,OR(_xlpm.x))))} -> AI Var 5 - SVideo Captions
B10: Variables Ratio
B11: Features | D11: 0.9
B12: Design | D12: 0.1
B14: Score Summary
B15: Components | C15: Maximum | D15: Realized | E15: Harvested | G15: Score | H15: Description
B16: General | C16: =(MAX('AI Groups'!$C$3:$G$3)-$C$34) + 15 -> 19 | D16: =E16/C16 -> 0.78281395 | E16: =General!F58 -> 14.873465 | G16: 0 | H16: Ga kerjain sama sekali
B17: Components | C17: 12 | D17: =E17/C17 -> 0.64632204 | E17: =Components!F55 -> 7.7558645 | G17: 1 | H17: Kerjain minim bet
B18: Login Page | C18: 3 | D18: =E18/C18 -> 0.415 | E18: ='Login Page'!F28 -> 1.245 | G18: 2 | H18: Kerjain tapi tidak mengerti / Kerjain dikit
B19: Sign up Page | C19: 3 | D19: =E19/C19 -> 0.69464286 | E19: ='Sign Up Page'!F34 -> 2.0839286 | G19: 3 | H19: Kerjain + masih error dikit + mengerti
B20: Reset Password Page | C20: 3 | D20: =E20/C20 -> 0.64 | E20: ='Reset Password Page'!F31 -> 1.92 | G20: 4 | H20: gacor + ngerti
B21: For You Page | C21: 5 | D21: =E21/C21 -> 0.62857143 | E21: ='For You Page'!F25 -> 3.1428571
B22: Following Page | C22: 2 | D22: =E22/C22 -> 0.54672414 | E22: ='Following Page'!F27 -> 1.0934483
B23: Friends Page | C23: 2 | D23: =E23/C23 -> 0.57172414 | E23: ='Friends Page'!F27 -> 1.1434483
B24: Profile Page | C24: 4 | D24: =E24/C24 -> 0.53497217 | E24: ='Profile Page'!F50 -> 2.1398887
B25: Create Playlist Page | C25: 2 | D25: =E25/C25 -> 0.9375 | E25: ='Create Playlist Page'!F27 -> 1.875
B26: Search Page | C26: 3 | D26: =E26/C26 -> 0.66892857 | E26: ='Search Page'!F30 -> 2.0067857
B27: Rich Text | C27: 1 | D27: =E27/C27 -> 0.83333333 | E27: ='Rich Text'!F10 -> 0.83333333
B28: Settings Page | C28: 4 | D28: =E28/C28 -> 0.32327586 | E28: ='Settings Page'!F29 -> 1.2931034
B29: Advertisement | C29: 1 | D29: =E29/C29 -> 1 | E29: =Advertisement!F6 -> 1
B30: Studio Upload Page | C30: 5 | D30: =E30/C30 -> 0.715625 | E30: ='Studio Upload Page'!F31 -> 3.578125
B31: Studio Post Page | C31: 4 | D31: =E31/C31 -> 0.64481707 | E31: ='Studio Post Page'!F37 -> 2.5792683
B32: Chat Page | C32: 7 | D32: =E32/C32 -> 0.60269784 | E32: ='Chat Page'!F45 -> 4.2188849
B33: Live | C33: 5 | D33: =E33/C33 -> 0.47230038 | E33: =Live!F47 -> 2.3615019
B34: AI | C34: =INDEX('AI Groups'!C3:G3,MATCH(Master!$D$8,'AI Groups'!C2:G2)) -> 8 | D34: =E34/C34 -> 0.89 | E34: {=INDIRECT("'" & $D$8 & "'!A1")} -> 7.12
B35: AI Knowledge | C35: 2 | D35: =E35/C35 -> 0 | E35: ='AI Knowledge'!G8 -> 0
B36: Web Knowledge | C36: 2 | D36: =E36/C36 -> 0 | E36: ='Web Knowledge'!G8 -> 0
B37: Web Coding Skill | C37: 1 | D37: =E37/C37 -> 0.36363636 | E37: ='Web Coding Skill'!F9 -> 0.36363636
B38: Live Coding | C38: 2 | D38: =E38/C38 -> 1 | E38: ='Live Coding'!F5 -> 2
B39: Total | C39: =ROUND(SUM(C16:C38), 0) -> 100 | E39: =SUM(E16:E38) -> 64.62754
B40: Realized | D40: =E39/C39 -> 0.6462754
B41: Harvested | D41: =D40 * 100 -> 64.62754

Sheet AI Groups
C2: AI Var 1 - SVilter | D2: AI Var 2 - SVign | E2: AI Var 3 - SaVe | F2: AI Var 4 - ShaVam | G2: AI Var 5 - SVideo Captions
C3: 10 | D3: 12 | E3: 8 | F3: 10 | G3: 8
C4: VW | D4: NW | E4: AA | F4: NV | G4: PC
C5: NG | D5: CY | E5: OI | F5: CK | G5: KN
C6: NP | D6: ES | E6: KF | F6: EV | G6: WE
C7: FB | D7: IL | E7: AT | F7: IV | G7: MX
C8: RL | D8: GS | F8: OW
C13: VW | D13: AI Var 1 - Svilter
C14: NG | D14: AI Var 1 - SVilter
C15: NP | D15: AI Var 1 - SVilter
C16: FB | D16: AI Var 1 - SVilter
C17: RL | D17: AI Var 1 - SVilter
C18: NW | D18: AI Var 2 - SVign
C19: CY | D19: AI Var 2 - SVign
C20: ES | D20: AI Var 2 - SVign
C21: IL | D21: AI Var 2 - SVign
C22: GS | D22: AI Var 2 - SVign
C23: AA | D23: AI Var 3 - SaVe
C24: OI | D24: AI Var 3 - SaVe
... C35: MX | D35: AI Var 5 - SVideo Captions

Sheet General
B2: {=RIGHT(CELL("filename", A1), LEN(CELL("filename", A1)) - FIND("]", CELL("filename", A1)))} -> General | F2: =VLOOKUP(B2,Master!B16:C38,2,FALSE) -> 19
B4: General & Technologies | C4: 0.67 | F4: =C4*F2 -> 12.73
B5: Requirement | C5: Max | D5: Weight | E5: Score | F5: Harvested
B6: Explain gRPC | C6: =D6*$F$4/$D$31 -> 0.88813953 | D6: 6 | E6: 4 | F6: =E6/4 * C6 -> 0.88813953
B7: Implement gRPC | C7: =D7*$F$4/$D$31 -> 0.29604651 | D7: 2 | E7: 4 | F7: =E7/4 * C7 -> 0.29604651
B8: Explain gRPC-Web | C8: =D8*$F$4/$D$31 -> 0.88813953 | D8: 6 | E8: 4 | F8: =E8/4 * C8 -> 0.88813953
B9: Implement gRPC-Web | C9: =D9*$F$4/$D$31 -> 0.29604651 | D9: 2 | E9: 4 | F9: =E9/4 * C9 -> 0.29604651
B10: Configure and explain Envoy | C10: =D10*$F$4/$D$31 -> 0.88813953 | D10: 6 | E10: 4 | F10: =E10/4 * C10 -> 0.88813953
B11: MinIO | C11: =D11*$F$4/$D$31 -> 0.88813953 | D11: 6 | E11: 4 | F11: =E11/4 * C11 -> 0.88813953
B12: MinIO Bucket Security | C12: =D12*$F$4/$D$31 -> 0.88813953 | D12: 6 | E12: 4 | F12: =E12/4 * C12 -> 0.88813953
B13: Streaming Implementation | C13: =D13*$F$4/$D$31 -> 0.88813953 | D13: 6 | E13: 0 | F13: =E13/4 * C13 -> 0
B14: Postman Documentation | C14: =D14*$F$4/$D$31 -> 0.14802326 | D14: 1 | E14: 4 | F14: =E14/4 * C14 -> 0.14802326
B15: Follow Git Best Practices | C15: =D15*$F$4/$D$31 -> 0.14802326 | D15: 1 | E15: 0 | F15: =E15/4 * C15 -> 0
B16: Implement and explain Microservice | C16: =D16*$F$4/$D$31 -> 0.29604651 | D16: 2 | E16: 4 | F16: =E16/4 * C16 -> 0.29604651
B17: Implement Database-per-Service | C17: =D17*$F$4/$D$31 -> 0.14802326 | D17: 1 | E17: 4 | F17: =E17/4 * C17 -> 0.14802326
... B30: Error Message and Code | C30: =D30*$F$4/$D$31 -> 0.29604651 | D30: 2 | E30: 0 | F30: =E30/4 * C30 -> 0
B31: Total | C31: =SUM(C6:C30) -> 12.73 | D31: =SUM(D6:D30) -> 86 | F31: =SUM(F6:F30) -> 9.3254651
B33: Containerization | C33: 0.08 | F33: =C33*F2 -> 1.52
B34: Requirement | C34: Max | D34: Weight | E34: Score | F34: Harvested
B35: Explain Containerization | C35: =D35*$F$33/$D$45 -> 0.152 | D35: 1 | E35: 4 | F35: =E35/4 * C35 -> 0.152
B36: Env File | C36: =D36*$F$33/$D$45 -> 0.152 | D36: 1 | E36: 4 | F36: =E36/4 * C36 -> 0.152
B37: Dockerfile (Frontend) | C37: =D37*$F$33/$D$45 -> 0.152 | D37: 1 | E37: 4 | F37: =E37/4 * C37 -> 0.152
B38: Dockerfile (Backend) | C38: =D38*$F$33/$D$45 -> 0.152 | D38: 1 | E38: 4 | F38: =E38/4 * C38 -> 0.152
B39: Dockerfile (AI) | C39: =D39*$F$33/$D$45 -> 0.152 | D39: 1 | E39: 2 | F39: =E39/4 * C39 -> 0.076
B40: Dockerfile (Envoy) | C40: =D40*$F$33/$D$45 -> 0.152 | D40: 1 | E40: 4 | F40: =E40/4 * C40 -> 0.152
B41: Docker Compose (DB) | C41: =D41*$F$33/$D$45 -> 0.152 | D41: 1 | E41: 4 | F41: =E41/4 * C41 -> 0.152
B42: Docker Compose (Minio) | C42: =D42*$F$33/$D$45 -> 0.152 | D42: 1 | E42: 4 | F42: =E42/4 * C42 -> 0.152
B43: Docker Compose (Memcached) | C43: =D43*$F$33/$D$45 -> 0.152 | D43: 1 | E43: 4 | F43: =E43/4 * C43 -> 0.152
B44: Docker Compose (Other) | C44: =D44*$F$33/$D$45 -> 0.152 | D44: 1 | E44: 2 | F44: =E44/4 * C44 -> 0.076
B45: Total | C45: =SUM(C35:C44) -> 1.52 | D45: =SUM(D35:D44) -> 10 | F45: =SUM(F35:F44) -> 1.368
B47: Security | C47: 0.25 | F47: =C47*F2 -> 4.75
B48: Requirement | C48: Max | D48: Weight | E48: Score | F48: Harvested
B49: Implementation Middleware on Frontend | C49: =D49*$F$47/$D$56 -> 0.76 | D49: 20 | E49: 4 | F49: =E49/4 * C49 -> 0.76
B50: Implemention Middleware on Backend | C50: =D50*$F$47/$D$56 -> 1.52 | D50: 40 | E50: 4 | F50: =E50/4 * C50 -> 1.52
B51: Middleware Efficiency | C51: =D51*$F$47/$D$56 -> 1.14 | D51: 30 | E51: 4 | F51: =E51/4 * C51 -> 1.14
B52: Hash Password | C52: =D52*$F$47/$D$56 -> 0.076 | D52: 2 | E52: 4 | F52: =E52/4 * C52 -> 0.076
B53: Implement and explain Paseto | C53: =D53*$F$47/$D$56 -> 0.38 | D53: 10 | E53: 2 | F53: =E53/4 * C53 -> 0.19
B54: Refresh Token | C54: =D54*$F$47/$D$56 -> 0.76 | D54: 20 | E54: 2 | F54: =E54/4 * C54 -> 0.38
B55: Toggle Follow Button Visibility | C55: =D55*$F$47/$D$56 -> 0.114 | D55: 3 | E55: 4 | F55: =E55/4 * C55 -> 0.114
B56: Total | C56: =SUM(C49:C55) -> 4.75 | D56: =SUM(D49:D55) -> 125 | F56: =SUM(F49:F55) -> 4.18
...

Sheet Components
B2: {=RIGHT(CELL("filename", A1), LEN(CELL("filename", A1)) - FIND("]", CELL("filename", A1)))} -> Components | F2: =VLOOKUP(B2,Master!B16:C38,2,FALSE) -> 12
B5: Video Detail | C5: 0.75 | F5: =C5*F2 -> 9 | K5: Sidebar Component | L5: 0.25 | O5: =L5*F2 -> 3
B7: Page Features | C7: =Master!$D$11 -> 0.9 | F7: =C7*F5 -> 8.1 | K7: Page Features | L7: =Master!$D$11 -> 0.9 | O7: =L7*O5 -> 2.7
B8: Requirement | C8: Max | D8: Weight | E8: Score | F8: Harvested | K8: Requirement | L8: Max | M8: Weight | N8: Score | O8: Harvested | Q8: Score Detail | R8: Total Detail
B9: Video | H9: Score Detail | I9: Total Detail | K9: Link Menu Completeness (Authorized) | L9: =M9/$M$29*$O$7 -> 0.084375 | M9: 2 | N9: =Q9*4/R9 -> 1.6666667 | O9: =N9/4 * L9 -> 0.03515625 | Q9: 5 | R9: 12
B10: Display Profile Picture, Username | C10: =D10/$D$42*$F$7 -> 0.26557377 | D10: 2 | E10: =H10*4/I10 -> 4 | F10: =E10/4 * C10 -> 0.26557377 | H10: 2 | I10: 2 | K10: Link Menu Completeness | L10: =M10/$M$29*$O$7 -> 0.084375 | M10: 2 | N10: =Q10*4/R10 -> 1.2 | O10: =N10/4 * L10 -> 0.0253125 | Q10: =1+0+1+1+0 -> 3 | R10: 10
B11: Display Follow Button to Follow Creator (if Not Following) | C11: =D11/$D$42*$F$7 -> 0.26557377 | D11: 2 | E11: 4 | F11: =E11/4 * C11 -> 0.26557377 | K11: "More" Drop down | L11: =M11/$M$29*$O$7 -> 0.0421875 | M11: 1 | N11: 4 | O11: =N11/4 * L11 -> 0.0421875
B12: Redirect to Creator's Profile Page | C12: =D12/$D$42*$F$7 -> 0.13278689 | D12: 1 | E12: 4 | F12: =E12/4 * C12 -> 0.13278689 | K12: Active Menu Highlight | L12: =M12/$M$29*$O$7 -> 0.0421875 | M12: 1 | N12: 4 | O12: =N12/4 * L12 -> 0.0421875
B13: Display Live badge (if Live Stream) | C13: =D13/$D$42*$F$7 -> 0.13278689 | D13: 1 | E13: 0 | F13: =E13/4 * C13 -> 0 | K13: Independent Scroll | L13: =M13/$M$29*$O$7 -> 0.084375 | M13: 2 | N13: 4 | O13: =N13/4 * L13 -> 0.084375
B14: Redirect to Live Stream Detail Page | C14: =D14/$D$42*$F$7 -> 0.26557377 | D14: 2 | E14: 0 | F14: =E14/4 * C14 -> 0 | K14: Logout | L14: =M14/$M$29*$O$7 -> 0.2109375 | M14: 5 | N14: 4 | O14: =N14/4 * L14 -> 0.2109375
B15: Video description with Rich Text | C15: =D15/$D$42*$F$7 -> 0.26557377 | D15: 2 | E15: 4 | F15: =E15/4 * C15 -> 0.26557377 | K15: Search Redirect | L15: =M15/$M$29*$O$7 -> 0.084375 | M15: 2 | N15: 3 | O15: =N15/4 * L15 -> 0.06328125
B16: Expand Video description with 'See More' | C16: =D16/$D$42*$F$7 -> 0.13278689 | D16: 1 | E16: 4 | F16: =E16/4 * C16 -> 0.13278689 | K16: Display Search History | L16: =M16/$M$29*$O$7 -> 0.3375 | M16: 8 | N16: 0 | O16: =N16/4 * L16 -> 0
B17: Display Like, Comment, Share, Favorite Count | C17: =D17/$D$42*$F$7 -> 0.53114754 | D17: 4 | E17: 2 | F17: =E17/4 * C17 -> 0.26557377 | K17: Clear History (Individual) | L17: =M17/$M$29*$O$7 -> 0.1265625 | M17: 3 | N17: 0 | O17: =N17/4 * L17 -> 0
B18: Like Button can Toggle Video Like | C18: =D18/$D$42*$F$7 -> 0.39836066 | D18: 3 | E18: 4 | F18: =E18/4 * C18 -> 0.39836066 | K18: Clear History (All) | L18: =M18/$M$29*$O$7 -> 0.1265625 | M18: 3 | N18: 0 | O18: =N18/4 * L18 -> 0
B19: 'Add to Favorite' Button can Toggle Favorites | C19: =D19/$D$42*$F$7 -> 0.39836066 | D19: 3 | E19: 0 | F19: =E19/4 * C19 -> 0 | K19: Default Theme | L19: =M19/$M$29*$O$7 -> 0.3375 | M19: 8 | N19: 0 | O19: =N19/4 * L19 -> 0
B20: Share Button to Open Share Section | C20: =D20/$D$42*$F$7 -> 0.13278689 | D20: 1 | E20: 0 | F20: =E20/4 * C20 -> 0 | K20: Theme | L20: =M20/$M$29*$O$7 -> 0.3375 | M20: 8 | N20: 0 | O20: =N20/4 * L20 -> 0
B21: Comment Button to Toggle Comment Section | C21: =D21/$D$42*$F$7 -> 0.13278689 | D21: 1 | E21: 4 | F21: =E21/4 * C21 -> 0.13278689 | K21: Debounce Search | L21: =M21/$M$29*$O$7 -> 0.1265625 | M21: 3 | N21: 4 | O21: =N21/4 * L21 -> 0.1265625
B22: Comment | K22: Display List of following account (if Authorized) | L22: =M22/$M$29*$O$7 -> 0.1265625 | M22: 3 | N22: 4 | O22: =N22/4 * L22 -> 0.1265625
B23: Display Profile Picture, Username, Timestamp | C23: =D23/$D$42*$F$7 -> 0.26557377 | D23: 2 | E23: 3 | F23: =E23/4 * C23 -> 0.19918033 | K23: Account Detail | L23: =M23/$M$29*$O$7 -> 0.1265625 | M23: 3 | N23: =Q23*4/R23 -> 4 | O23: =N23/4 * L23 -> 0.1265625 | Q23: 3 | R23: 3
B24: Comment with Rich Text | C24: =D24/$D$42*$F$7 -> 0.26557377 | D24: 2 | E24: 4 | F24: =E24/4 * C24 -> 0.26557377 | K24: See more (Following account) | L24: =M24/$M$29*$O$7 -> 0.1265625 | M24: 3 | N24: 3 | O24: =N24/4 * L24 -> 0.094921875
B25: Expand Comment with 'See More' | C25: =D25/$D$42*$F$7 -> 0.13278689 | D25: 1 | E25: 0 | F25: =E25/4 * C25 -> 0 | K25: Redirect specific user profile | L25: =M25/$M$29*$O$7 -> 0.084375 | M25: 2 | N25: 4 | O25: =N25/4 * L25 -> 0.084375
B26: Toggle Like Button for Comments and Replies | C26: =D26/$D$42*$F$7 -> 0.39836066 | D26: 3 | E26: 4 | F26: =E26/4 * C26 -> 0.39836066 | K26: Display Link and can redirect (Footer) | L26: =M26/$M$29*$O$7 -> 0.0421875 | M26: 1 | N26: =Q26*4/R26 -> 0 | O26: =N26/4 * L26 -> 0 | Q26: 0 | R26: 6
B27: View Replies | C27: =D27/$D$42*$F$7 -> 0.13278689 | D27: 1 | E27: 4 | F27: =E27/4 * C27 -> 0.13278689 | K27: Cache Data for Backend | L27: =M27/$M$29*$O$7 -> 0.084375 | M27: 2 | N27: 0 | O27: =N27/4 * L27 -> 0
B28: Send Comments and Replies | C28: =D28/$D$42*$F$7 -> 0.39836066 | D28: 3 | E28: 4 | F28: =E28/4 * C28 -> 0.39836066 | K28: Cache Data for Frontend | L28: =M28/$M$29*$O$7 -> 0.084375 | M28: 2 | N28: 0 | O28: =N28/4 * L28 -> 0
B29: Unsend Comments and Replies | C29: =D29/$D$42*$F$7 -> 0.39836066 | D29: 3 | E29: 4 | F29: =E29/4 * C29 -> 0.39836066 | K29: Total | L29: =SUM(L9:L28) -> 2.7 | M29: =SUM(M9:M28) -> 64 | O29: =SUM(O9:O28) -> 1.0624219
B30: Display Likes Count for Comments and Replies | C30: =D30/$D$42*$F$7 -> 0.26557377 | D30: 2 | E30: 4 | F30: =E30/4 * C30 -> 0.26557377
B31: Share | K31: Page Design | L31: =Master!$D$12 -> 0.1 | O31: =L31*O5 -> 0.3
B32: Can Copy Video URL | C32: =D32/$D$42*$F$7 -> 0.13278689 | D32: 1 | E32: 4 | F32: =E32/4 * C32 -> 0.13278689 | K32: Requirement | L32: Max | M32: Weight | N32: Score | O32: Harvested
B33: Share using Message | C33: =D33/$D$42*$F$7 -> 0.53114754 | D33: 4 | E33: 2 | F33: =E33/4 * C33 -> 0.26557377 | K33: Aesthetic | L33: =M33/$M$37*$O$31 -> 0.085714286 | M33: 2 | N33: 2 | O33: =N33/4 * L33 -> 0.042857143
B34: Download Video | C34: =D34/$D$42*$F$7 -> 0.53114754 | D34: 4 | E34: 4 | F34: =E34/4 * C34 -> 0.53114754 | K34: Accessibility | L34: =M34/$M$37*$O$31 -> 0.12857143 | M34: 3 | N34: 2 | O34: =N34/4 * L34 -> 0.064285714
B35: Navigation and Caching | K35: Rounded Consistency | L35: =M35/$M$37*$O$31 -> 0.042857143 | M35: 1 | N35: 2 | O35: =N35/4 * L35 -> 0.021428571
B36: Next and Previous Button to Navigate | C36: =D36/$D$42*$F$7 -> 0.26557377 | D36: 2 | E36: 4 | F36: =E36/4 * C36 -> 0.26557377 | K36: Padding | L36: =M36/$M$37*$O$31 -> 0.042857143 | M36: 1 | N36: 2 | O36: =N36/4 * L36 -> 0.021428571
B37: Can Navigate using Scroll with Mouse | C37: =D37/$D$42*$F$7 -> 0.39836066 | D37: 3 | E37: 4 | F37: =E37/4 * C37 -> 0.39836066 | K37: Total | L37: =SUM(L33:L36) -> 0.3 | M37: =SUM(M33:M36) -> 7 | O37: =SUM(O33:O36) -> 0.15
B38: Scroll Snap | C38: =D38/$D$42*$F$7 -> 0.13278689 | D38: 1 | E38: 4 | F38: =E38/4 * C38 -> 0.13278689
B39: Loading Skeleton | C39: =D39/$D$42*$F$7 -> 0.26557377 | D39: 2 | E39: 0 | F39: =E39/4 * C39 -> 0 | K39: Subtotal | O39: =SUM(O29,O37) -> 1.2124219
B40: Cache Data for Backend | C40: =D40/$D$42*$F$7 -> 0.26557377 | D40: 2 | E40: 0 | F40: =E40/4 * C40 -> 0
B41: Cache Data for Frontend | C41: =D41/$D$42*$F$7 -> 0.26557377 | D41: 2 | E41: 0 | F41: =E41/4 * C41 -> 0
B42: Total | C42: =SUM(C10:C41) -> 8.1 | D42: =SUM(D10:D41) -> 61 | F42: =SUM(F10:F41) -> 5.6434426
B44: Page Design | C44: =Master!$D$12 -> 0.1 | F44: =C44*F5 -> 0.9
B45: Requirement | C45: Max | D45: Weight | E45: Score | F45: Harvested
...

Sheet Sign Up Page
B2: {=RIGHT(CELL("filename", A1), LEN(CELL("filename", A1)) - FIND("]", CELL("filename", A1)))} -> Sign Up Page | F2: =VLOOKUP(B2,Master!B16:C38,2,FALSE) -> 3
B4: Page Features | C4: =Master!$D$11 -> 0.9 | F4: =C4*F2 -> 2.7
B5: Requirement | C5: Max | D5: Weight | E5: Score | F5: Harvested
B6: Redirect to Other Page if Authenticated | C6: =D6/$D$23*$F$4 -> 0.032142857 | D6: 1 | E6: 4 | F6: =E6/4*C6 -> 0.032142857 | H6: Score Detail | I6: Total Detail
B7: Link to Other Pages | C7: =D7/$D$23*$F$4 -> 0.032142857 | D7: 1 | E7: =H7*4/I7 -> 4 | F7: =E7/4*C7 -> 0.032142857 | H7: 4 | I7: 4
B8: Form Completeness | C8: =D8/$D$23*$F$4 -> 0.064285714 | D8: 2 | E8: =H8*4/I8 -> 4 | F8: =E8/4*C8 -> 0.064285714 | H8: 7 | I8: 7
B9: Validate Email is Unique | C9: =D9/$D$23*$F$4 -> 0.096428571 | D9: 3 | E9: 4 | F9: =E9/4*C9 -> 0.096428571
B10: Validate Username Unique | C10: =D10/$D$23*$F$4 -> 0.096428571 | D10: 3 | E10: 4 | F10: =E10/4*C10 -> 0.096428571
B11: Validate OTP Code is Correct | C11: =D11/$D$23*$F$4 -> 0.096428571 | D11: 3 | E11: 4 | F11: =E11/4*C11 -> 0.096428571
B12: Rate Limit OTP Code | C12: =D12/$D$23*$F$4 -> 0.64285714 | D12: 20 | E12: 4 | F12: =E12/4*C12 -> 0.64285714
B13: Resend OTP Code | C13: =D13/$D$23*$F$4 -> 0.096428571 | D13: 3 | E13: 4 | F13: =E13/4*C13 -> 0.096428571
B14: Send OTP Code | C14: =D14/$D$23*$F$4 -> 0.096428571 | D14: 3 | E14: 4 | F14: =E14/4*C14 -> 0.096428571
B15: Validate if OTP has Expired (10 Minutes) | C15: =D15/$D$23*$F$4 -> 0.32142857 | D15: 10 | E15: 4 | F15: =E15/4*C15 -> 0.32142857
B16: Google Authentication | C16: =D16/$D$23*$F$4 -> 0.64285714 | D16: 20 | E16: 0 | F16: =E16/4*C16 -> 0
B17: Register Logic | C17: =D17/$D$23*$F$4 -> 0.16071429 | D17: 5 | E17: 2 | F17: =E17/4*C17 -> 0.080357143
B18: Redirect after success | C18: =D18/$D$23*$F$4 -> 0.032142857 | D18: 1 | E18: 4 | F18: =E18/4*C18 -> 0.032142857
B19: Email Design | C19: =D19/$D$23*$F$4 -> 0.064285714 | D19: 2 | E19: 0 | F19: =E19/4*C19 -> 0
B20: Send email with correct content | C20: =D20/$D$23*$F$4 -> 0.096428571 | D20: 3 | E20: 4 | F20: =E20/4*C20 -> 0.096428571
... B22: Cache Data for Frontend | C22: =D22/$D$23*$F$4 -> 0.064285714 | D22: 2 | E22: 0 | F22: =E22/4*C22 -> 0
B23: Total | C23: =SUM(C6:C22) -> 2.7 | D23: =SUM(D6:D22) -> 84 | F23: =SUM(F6:F22) -> 1.7839286
B25: Page Design | C25: =Master!$D$12 -> 0.1 | F25: =C25*F2 -> 0.3
B26: Requirement | C26: Max | D26: Weight | E26: Score | F26: Harvested
B27: Aesthetic | C27: =D27/$D$32*$F$25 -> 0.06 | D27: 2 | E27: 4 | F27: =E27/4 * C27 -> 0.06
B28: Accessibility | C28: =D28/$D$32*$F$25 -> 0.09 | D28: 3 | E28: 4 | F28: =E28/4 * C28 -> 0.09
B29: Rounded Consistency | C29: =D29/$D$32*$F$25 -> 0.03 | D29: 1 | E29: 4 | F29: =E29/4 * C29 -> 0.03
B30: Padding | C30: =D30/$D$32*$F$25 -> 0.03 | D30: 1 | E30: 4 | F30: =E30/4 * C30 -> 0.03
B31: Error Message | C31: =D31/$D$32*$F$25 -> 0.09 | D31: 3 | E31: 4 | F31: =E31/4 * C31 -> 0.09
B32: Total | C32: =SUM(C27:C31) -> 0.3 | D32: =SUM(D27:D31) -> 10 | F32: =SUM(F27:F31) -> 0.3
B34: Grand Total | F34: =SUM(F23,F32) -> 2.0839286

Sheet Login Page
B2: {=RIGHT(CELL("filename", A1), LEN(CELL("filename", A1)) - FIND("]", CELL("filename", A1)))} -> Login Page | F2: =VLOOKUP(B2,Master!B16:C38,2,FALSE) -> 3
B4: Page Features | C4: =Master!$D$11 -> 0.9 | F4: =C4*F2 -> 2.7
B5: Requirement | C5: Max | D5: Weight | E5: Score | F5: Harvested
B6: Redirect to Other Page if Authenticated | C6: =D6/$D$17*$F$4 -> 0.18 | D6: 2 | E6: 4 | F6: =E6/4*C6 -> 0.18
B7: Other Pages Redirects Here if not Authenticated | C7: =D7/$D$17*$F$4 -> 0.18 | D7: 2 | E7: 4 | F7: =E7/4*C7 -> 0.18 | H7: Score Detail | I7: Total Detail
B8: Link to Other Pages | C8: =D8/$D$17*$F$4 -> 0.09 | D8: 1 | E8: =H8*4/I8 -> 4 | F8: =E8/4*C8 -> 0.09 | H8: 6 | I8: 6
B9: Form Completeness | C9: =D9/$D$17*$F$4 -> 0.18 | D9: 2 | E9: =H9*4/I9 -> 4 | F9: =E9/4*C9 -> 0.18 | H9: 3 | I9: 3
B10: Login Logic | C10: =D10/$D$17*$F$4 -> 0.45 | D10: 5 | E10: 2 | F10: =E10/4*C10 -> 0.225
B11: Google Authentication | C11: =D11/$D$17*$F$4 -> 0.9 | D11: 10 | E11: 0 | F11: =E11/4*C11 -> 0
B12: Redirect after success | C12: =D12/$D$17*$F$4 -> 0.09 | D12: 1 | E12: 4 | F12: =E12/4*C12 -> 0.09
B13: Email Design | C13: =D13/$D$17*$F$4 -> 0.18 | D13: 2 | E13: 0 | F13: =E13/4*C13 -> 0
B14: Send email with correct content | C14: =D14/$D$17*$F$4 -> 0.27 | D14: 3 | E14: 0 | F14: =E14/4*C14 -> 0
B15: Cache Data for Backend | C15: =D15/$D$17*$F$4 -> 0.09 | D15: 1 | E15: 0 | F15: =E15/4*C15 -> 0
B16: Cache Data for Frontend | C16: =D16/$D$17*$F$4 -> 0.09 | D16: 1 | E16: 0 | F16: =E16/4*C16 -> 0
B17: Total | C17: =SUM(C6:C16) -> 2.7 | D17: =SUM(D6:D16) -> 30 | F17: =SUM(F6:F16) -> 0.945
B19: Page Design | C19: =Master!$D$12 -> 0.1 | F19: =C19*F2 -> 0.3
B20: Requirement | C20: Max | D20: Weight | E20: Score | F20: Harvested
B21: Aesthetic | C21: =D21/$D$26*$F$19 -> 0.06 | D21: 2 | E21: 4 | F21: =E21/4 * C21 -> 0.06
B22: Accessibility | C22: =D22/$D$26*$F$19 -> 0.09 | D22: 3 | E22: 4 | F22: =E22/4 * C22 -> 0.09
B23: Rounded Consistency | C23: =D23/$D$26*$F$19 -> 0.03 | D23: 1 | E23: 4 | F23: =E23/4 * C23 -> 0.03
B24: Padding | C24: =D24/$D$26*$F$19 -> 0.03 | D24: 1 | E24: 4 | F24: =E24/4 * C24 -> 0.03
B25: Error Message | C25: =D25/$D$26*$F$19 -> 0.09 | D25: 3 | E25: 4 | F25: =E25/4 * C25 -> 0.09
B26: Total | C26: =SUM(C21:C25) -> 0.3 | D26: =SUM(D21:D25) -> 10 | F26: =SUM(F21:F25) -> 0.3
B28: Grand Total | F28: =SUM(F17,F26) -> 1.245

Sheet Reset Password Page
B2: {=RIGHT(CELL("filename", A1), LEN(CELL("filename", A1)) - FIND("]", CELL("filename", A1)))} -> Reset Password Page | F2: =VLOOKUP(B2,Master!B16:C38,2,FALSE) -> 3
B4: Page Features | C4: =Master!$D$11 -> 0.9 | F4: =C4*F2 -> 2.7
B5: Requirement | C5: Max | D5: Weight | E5: Score | F5: Harvested | H5: Score Detail | I5: Total Detail
B6: Link to Other Pages | C6: =D6/$D$20*$F$4 -> 0.054 | D6: 1 | E6: =H6*4/I6 -> 4 | F6: =E6/4*C6 -> 0.054 | H6: 4 | I6: 4
B7: Form Completeness | C7: =D7/$D$20*$F$4 -> 0.108 | D7: 2 | E7: =H7*4/I7 -> 4 | F7: =E7/4*C7 -> 0.108 | H7: 5 | I7: 5
B8: Validate New Password is Different | C8: =D8/$D$20*$F$4 -> 0.162 | D8: 3 | E8: 4 | F8: =E8/4*C8 -> 0.162
B9: Validate OTP Code is Correct | C9: =D9/$D$20*$F$4 -> 0.162 | D9: 3 | E9: 4 | F9: =E9/4*C9 -> 0.162
B10: Rate Limit OTP Code | C10: =D10/$D$20*$F$4 -> 0.54 | D10: 10 | E10: 4 | F10: =E10/4*C10 -> 0.54
B11: Send OTP Code | C11: =D11/$D$20*$F$4 -> 0.162 | D11: 3 | E11: 4 | F11: =E11/4*C11 -> 0.162
B12: Validate if OTP has Expired (10 Minutes) | C12: =D12/$D$20*$F$4 -> 0.27 | D12: 5 | E12: 4 | F12: =E12/4*C12 -> 0.27
B13: Invalidate Session | C13: =D13/$D$20*$F$4 -> 0.54 | D13: 10 | E13: 0 | F13: =E13/4*C13 -> 0
B14: Reset Password Logic | C14: =D14/$D$20*$F$4 -> 0.216 | D14: 4 | E14: 2 | F14: =E14/4*C14 -> 0.108
B15: Redirect after success | C15: =D15/$D$20*$F$4 -> 0.054 | D15: 1 | E15: 4 | F15: =E15/4*C15 -> 0.054
B16: Send email with correct content | C16: =D16/$D$20*$F$4 -> 0.162 | D16: 3 | E16: 0 | F16: =E16/4*C16 -> 0
B17: Email Design | C17: =D17/$D$20*$F$4 -> 0.162 | D17: 3 | E17: 0 | F17: =E17/4*C17 -> 0
B18: Cache Data for Backend | C18: =D18/$D$20*$F$4 -> 0.054 | D18: 1 | E18: 0 | F18: =E18/4*C18 -> 0
B19: Cache Data for Frontend | C19: =D19/$D$20*$F$4 -> 0.054 | D19: 1 | E19: 0 | F19: =E19/4*C19 -> 0
B20: Total | C20: =SUM(C6:C19) -> 2.7 | D20: =SUM(D6:D19) -> 50 | F20: =SUM(F6:F19) -> 1.62
B22: Page Design | C22: =Master!$D$12 -> 0.1 | F22: =C22*F2 -> 0.3
B23: Requirement | C23: Max | D23: Weight | E23: Score | F23: Harvested
B24: Aesthetic | C24: =D24/$D$29*$F$22 -> 0.06 | D24: 2 | E24: 4 | F24: =E24/4 * C24 -> 0.06
B25: Accessibility | C25: =D25/$D$29*$F$22 -> 0.09 | D25: 3 | E25: 4 | F25: =E25/4 * C25 -> 0.09
B26: Rounded Consistency | C26: =D26/$D$29*$F$22 -> 0.03 | D26: 1 | E26: 4 | F26: =E26/4 * C26 -> 0.03
B27: Padding | C27: =D27/$D$29*$F$22 -> 0.03 | D27: 1 | E27: 4 | F27: =E27/4 * C27 -> 0.03
B28: Error Message | C28: =D28/$D$29*$F$22 -> 0.09 | D28: 3 | E28: 4 | F28: =E28/4 * C28 -> 0.09
B29: Total | C29: =SUM(C24:C28) -> 0.3 | D29: =SUM(D24:D28) -> 10 | F29: =SUM(F24:F28) -> 0.3
B31: Grand Total | F31: =SUM(F20,F29) -> 1.92

Sheet For You Page
B2: {=RIGHT(CELL("filename", A1), LEN(CELL("filename", A1)) - FIND("]", CELL("filename", A1)))} -> For You Page | F2: =VLOOKUP(B2,Master!B16:C38,2,FALSE) -> 5
B4: Page Features | C4: =Master!$D$11 -> 0.9 | F4: =C4*F2 -> 4.5
B5: Requirement | C5: Max | D5: Weight | E5: Score | F5: Harvested
B6: Display Components | C6: =D6/$D$14*$F$4 -> 0.071428571 | D6: 0.5 | E6: 4 | F6: =E6/4*C6 -> 0.071428571
B7: Infinite Scrolling | C7: =D7/$D$14*$F$4 -> 0.57142857 | D7: 4 | E7: 0 | F7: =E7/4*C7 -> 0
B8: Prioritize New and Popular Videos | C8: =D8/$D$14*$F$4 -> 0.85714286 | D8: 6 | E8: 3 | F8: =E8/4*C8 -> 0.64285714
B9: Recommend Never Watched Videos (if Authorized) | C9: =D9/$D$14*$F$4 -> 0.85714286 | D9: 6 | E9: 3 | F9: =E9/4*C9 -> 0.64285714
B10: Shuffle with Weighted Randomization | C10: =D10/$D$14*$F$4 -> 0.85714286 | D10: 6 | E10: 3 | F10: =E10/4*C10 -> 0.64285714
B11: Occasionally Mix Random Other Videos | C11: =D11/$D$14*$F$4 -> 0.85714286 | D11: 6 | E11: 3 | F11: =E11/4*C11 -> 0.64285714
B12: Cache Data for Backend | C12: =D12/$D$14*$F$4 -> 0.21428571 | D12: 1.5 | E12: 0 | F12: =E12/4*C12 -> 0
B13: Cache Data for Frontend | C13: =D13/$D$14*$F$4 -> 0.21428571 | D13: 1.5 | E13: 0 | F13: =E13/4*C13 -> 0
B14: Total | C14: =SUM(C6:C13) -> 4.5 | D14: =SUM(D6:D13) -> 31.5 | F14: =SUM(F6:F13) -> 2.6428571
B16: Page Design | C16: =Master!$D$12 -> 0.1 | F16: =C16*F2 -> 0.5
B17: Requirement | C17: Max | D17: Weight | E17: Score | F17: Harvested
B18: Aesthetic | C18: =D18/$D$23*$F$16 -> 0.1 | D18: 2 | E18: 4 | F18: =E18/4 * C18 -> 0.1
B19: Accessibility | C19: =D19/$D$23*$F$16 -> 0.15 | D19: 3 | E19: 4 | F19: =E19/4 * C19 -> 0.15
B20: Responsive | C20: =D20/$D$23*$F$16 -> 0.15 | D20: 3 | E20: 4 | F20: =E20/4 * C20 -> 0.15
B21: Rounded Consistency | C21: =D21/$D$23*$F$16 -> 0.05 | D21: 1 | E21: 4 | F21: =E21/4 * C21 -> 0.05
B22: Padding | C22: =D22/$D$23*$F$16 -> 0.05 | D22: 1 | E22: 4 | F22: =E22/4 * C22 -> 0.05
B23: Total | C23: =SUM(C18:C22) -> 0.5 | D23: =SUM(D18:D22) -> 10 | F23: =SUM(F18:F22) -> 0.5
B25: Grand Total | F25: =SUM(F14,F23) -> 3.1428571

Sheet Following Page
B2: {=RIGHT(CELL("filename", A1), LEN(CELL("filename", A1)) - FIND("]", CELL("filename", A1)))} -> Following Page | F2: =VLOOKUP(B2,Master!B16:C38,2,FALSE) -> 2
B4: Page Features | C4: =Master!$D$11 -> 0.9 | F4: =C4*F2 -> 1.8
B5: Requirement | C5: Max | D5: Weight | E5: Score | F5: Harvested
B6: Display Components | C6: =D6/$D$16*$F$4 -> 0.062068966 | D6: 1 | E6: 4 | F6: =E6/4*C6 -> 0.062068966
B7: Redirect to Login Page if Unauthorized | C7: =D7/$D$16*$F$4 -> 0.12413793 | D7: 2 | E7: 4 | F7: =E7/4*C7 -> 0.12413793
B8: Infinite Scrolling | C8: =D8/$D$16*$F$4 -> 0.24827586 | D8: 4 | E8: 0 | F8: =E8/4*C8 -> 0 | H8: Score Detail | I8: Following Only | J8: Total Detail
B9: Display List of Random User (No Following) | C9: =D9/$D$16*$F$4 -> 0.24827586 | D9: 4 | E9: =(H9/J9*4)-((1-I9)*(H9/J9*2)) -> 3.2 | F9: =E9/4*C9 -> 0.19862069 | H9: 8 | I9: 1 | J9: 10
B10: Redirect to Respective Profile Page | C10: =D10/$D$16*$F$4 -> 0.062068966 | D10: 1 | E10: 4 | F10: =E10/4*C10 -> 0.062068966
B11: Display Live Account List | C11: =D11/$D$16*$F$4 -> 0.12413793 | D11: 2 | E11: 0 | F11: =E11/4*C11 -> 0
B12: Redirect to Respective Live Stream Detail | C12: =D12/$D$16*$F$4 -> 0.24827586 | D12: 4 | E12: 0 | F12: =E12/4*C12 -> 0
B13: Smart Algorithm (Following Only) | C13: =D13/$D$16*$F$4 -> 0.49655172 | D13: 8 | E13: 4 | F13: =E13/4*C13 -> 0.49655172
B14: Cache Data for Backend | C14: =D14/$D$16*$F$4 -> 0.093103448 | D14: 1.5 | E14: 0 | F14: =E14/4*C14 -> 0
B15: Cache Data for Frontend | C15: =D15/$D$16*$F$4 -> 0.093103448 | D15: 1.5 | E15: 0 | F15: =E15/4*C15 -> 0
B16: Total | C16: =SUM(C6:C15) -> 1.8 | D16: =SUM(D6:D15) -> 29 | F16: =SUM(F6:F15) -> 0.94344828
B18: Page Design | C18: =Master!$D$12 -> 0.1 | F18: =C18*F2 -> 0.2
B19: Requirement | C19: Max | D19: Weight | E19: Score | F19: Harvested
B20: Aesthetic | C20: =D20/$D$25*$F$18 -> 0.04 | D20: 2 | E20: 3 | F20: =E20/4 * C20 -> 0.03
B21: Accessibility | C21: =D21/$D$25*$F$18 -> 0.06 | D21: 3 | E21: 3 | F21: =E21/4 * C21 -> 0.045
B22: Responsive | C22: =D22/$D$25*$F$18 -> 0.06 | D22: 3 | E22: 3 | F22: =E22/4 * C22 -> 0.045
B23: Rounded Consistency | C23: =D23/$D$25*$F$18 -> 0.02 | D23: 1 | E23: 3 | F23: =E23/4 * C23 -> 0.015
B24: Padding | C24: =D24/$D$25*$F$18 -> 0.02 | D24: 1 | E24: 3 | F24: =E24/4 * C24 -> 0.015
B25: Total | C25: =SUM(C20:C24) -> 0.2 | D25: =SUM(D20:D24) -> 10 | F25: =SUM(F20:F24) -> 0.15
B27: Grand Total | F27: =SUM(F16,F25) -> 1.0934483

Sheet Friends Page
B2: {=RIGHT(CELL("filename", A1), LEN(CELL("filename", A1)) - FIND("]", CELL("filename", A1)))} -> Friends Page | F2: =VLOOKUP(B2,Master!B16:C38,2,FALSE) -> 2
B4: Page Features | C4: =Master!$D$11 -> 0.9 | F4: =C4*F2 -> 1.8
B5: Requirement | C5: Max | D5: Weight | E5: Score | F5: Harvested
B6: Display Components | C6: =D6/$D$16*$F$4 -> 0.062068966 | D6: 1 | E6: 4 | F6: =E6/4*C6 -> 0.062068966
B7: Redirect to Login Page if Unauthorized | C7: =D7/$D$16*$F$4 -> 0.12413793 | D7: 2 | E7: 4 | F7: =E7/4*C7 -> 0.12413793
B8: Infinite Scrolling | C8: =D8/$D$16*$F$4 -> 0.24827586 | D8: 4 | E8: 0 | F8: =E8/4*C8 -> 0 | H8: Score Detail | I8: Friends Only | J8: Total Detail
B9: List of Random User (Not Mutual) | C9: =D9/$D$16*$F$4 -> 0.24827586 | D9: 4 | E9: =(H9/J9*4)-((1-I9)*(H9/J9*2)) -> 3.2 | F9: =E9/4*C9 -> 0.19862069 | H9: 8 | I9: 1 | J9: 10
B10: Redirect to Respective Profile Page | C10: =D10/$D$16*$F$4 -> 0.062068966 | D10: 1 | E10: 4 | F10: =E10/4*C10 -> 0.062068966
B11: Display Live Account List | C11: =D11/$D$16*$F$4 -> 0.12413793 | D11: 2 | E11: 0 | F11: =E11/4*C11 -> 0
B12: Redirect to Respective Live Stream Detail | C12: =D12/$D$16*$F$4 -> 0.24827586 | D12: 4 | E12: 0 | F12: =E12/4*C12 -> 0
B13: Smart Algorithm (Friends Only) | C13: =D13/$D$16*$F$4 -> 0.49655172 | D13: 8 | E13: 4 | F13: =E13/4*C13 -> 0.49655172
B14: Cache Data for Backend | C14: =D14/$D$16*$F$4 -> 0.093103448 | D14: 1.5 | E14: 0 | F14: =E14/4*C14 -> 0
B15: Cache Data for Frontend | C15: =D15/$D$16*$F$4 -> 0.093103448 | D15: 1.5 | E15: 0 | F15: =E15/4*C15 -> 0
B16: Total | C16: =SUM(C6:C15) -> 1.8 | D16: =SUM(D6:D15) -> 29 | F16: =SUM(F6:F15) -> 0.94344828
B18: Page Design | C18: =Master!$D$12 -> 0.1 | F18: =C18*F2 -> 0.2
B19: Requirement | C19: Max | D19: Weight | E19: Score | F19: Harvested
B20: Aesthetic | C20: =D20/$D$25*$F$18 -> 0.04 | D20: 2 | E20: 4 | F20: =E20/4 * C20 -> 0.04
B21: Accessibility | C21: =D21/$D$25*$F$18 -> 0.06 | D21: 3 | E21: 4 | F21: =E21/4 * C21 -> 0.06
B22: Responsive | C22: =D22/$D$25*$F$18 -> 0.06 | D22: 3 | E22: 4 | F22: =E22/4 * C22 -> 0.06
B23: Rounded Consistency | C23: =D23/$D$25*$F$18 -> 0.02 | D23: 1 | E23: 4 | F23: =E23/4 * C23 -> 0.02
B24: Padding | C24: =D24/$D$25*$F$18 -> 0.02 | D24: 1 | E24: 4 | F24: =E24/4 * C24 -> 0.02
B25: Total | C25: =SUM(C20:C24) -> 0.2 | D25: =SUM(D20:D24) -> 10 | F25: =SUM(F20:F24) -> 0.2
B27: Grand Total | F27: =SUM(F16,F25) -> 1.1434483

Sheet Profile Page
B2: {=RIGHT(CELL("filename", A1), LEN(CELL("filename", A1)) - FIND("]", CELL("filename", A1)))} -> Profile Page | F2: =VLOOKUP(B2,Master!B16:C38,2,FALSE) -> 4
B4: Page Features | C4: =Master!$D$11 -> 0.9 | F4: =C4*F2 -> 3.6
B5: Requirement | C5: Max | D5: Weight | E5: Score | F5: Harvested
B6: Display Components | C6: =D6/$D$39*$F$4 -> 0.046753247 | D6: 1 | E6: 4 | F6: =E6/4*C6 -> 0.046753247 | H6: Score Detail | I6: Total Detail
B7: Display Profile Buttons | C7: =D7/$D$39*$F$4 -> 0.046753247 | D7: 1 | E7: =H7*4/I7 -> 4 | F7: =E7/4*C7 -> 0.046753247 | H7: 6 | I7: 6
B8: Display User Details | C8: =D8/$D$39*$F$4 -> 0.093506494 | D8: 2 | E8: =H8*4/I8 -> 3.4285714 | F8: =E8/4*C8 -> 0.080148423 | H8: 6 | I8: 7
B9: Follow/Unfollow Button is Functional | C9: =D9/$D$39*$F$4 -> 0.093506494 | D9: 2 | E9: 4 | F9: =E9/4*C9 -> 0.093506494
B10: Modal Follower | C10: =D10/$D$39*$F$4 -> 0.093506494 | D10: 2 | E10: 4 | F10: =E10/4*C10 -> 0.093506494
B11: Modal Following | C11: =D11/$D$39*$F$4 -> 0.093506494 | D11: 2 | E11: 4 | F11: =E11/4*C11 -> 0.093506494
B12: Following / Follower Detail Modal | C12: =D12/$D$39*$F$4 -> 0.093506494 | D12: 2 | E12: =H12*4/I12 -> 4 | F12: =E12/4*C12 -> 0.093506494 | H12: 3 | I12: 3
B13: Edit Profile Picture | C13: =D13/$D$39*$F$4 -> 0.093506494 | D13: 2 | E13: 2 | F13: =E13/4*C13 -> 0.046753247
B14: Edit User Profile | C14: =D14/$D$39*$F$4 -> 0.18701299 | D14: 4 | E14: 4 | F14: =E14/4*C14 -> 0.18701299
B15: Message Button Redirect | C15: =D15/$D$39*$F$4 -> 0.046753247 | D15: 1 | E15: 4 | F15: =E15/4*C15 -> 0.046753247
B16: Create Playlist Button Redirect | C16: =D16/$D$39*$F$4 -> 0.046753247 | D16: 1 | E16: 4 | F16: =E16/4*C16 -> 0.046753247
B17: Setting Button Redirect | C17: =D17/$D$39*$F$4 -> 0.046753247 | D17: 1 | E17: 2 | F17: =E17/4*C17 -> 0.023376623
B18: Share Button Functional | C18: =D18/$D$39*$F$4 -> 0.046753247 | D18: 1 | E18: 0 | F18: =E18/4*C18 -> 0
B19: Video Tab Visibility | C19: =D19/$D$39*$F$4 -> 0.14025974 | D19: 3 | E19: 0 | F19: =E19/4*C19 -> 0
B20: Playlist Card Details | C20: =D20/$D$39*$F$4 -> 0.14025974 | D20: 3 | E20: =H20*4/I20 -> 4 | F20: =E20/4*C20 -> 0.14025974 | H20: 2 | I20: 2
B21: Playlist Details | C21: =D21/$D$39*$F$4 -> 0.14025974 | D21: 3 | E21: =H21*4/I21 -> 1 | F21: =E21/4*C21 -> 0.035064935 | H21: 1 | I21: 4
B22: Playlist custom order | C22: =D22/$D$39*$F$4 -> 0.23376623 | D22: 5 | E22: 3 | F22: =E22/4*C22 -> 0.17532468
B23: Redirect to Video Detail (Playlist) | C23: =D23/$D$39*$F$4 -> 0.046753247 | D23: 1 | E23: 0 | F23: =E23/4*C23 -> 0
B24: Video Tab Details | C24: =D24/$D$39*$F$4 -> 0.14025974 | D24: 3 | E24: =H24*4/I24 -> 4 | F24: =E24/4*C24 -> 0.14025974 | H24: 3 | I24: 3
B25: Video Tab Redirect | C25: =D25/$D$39*$F$4 -> 0.046753247 | D25: 1 | E25: 2 | F25: =E25/4*C25 -> 0.023376623
B26: Favorite Tab Visibility | C26: =D26/$D$39*$F$4 -> 0.093506494 | D26: 2 | E26: 0 | F26: =E26/4*C26 -> 0
B27: Favorite Content | C27: =D27/$D$39*$F$4 -> 0.093506494 | D27: 2 | E27: 0 | F27: =E27/4*C27 -> 0
B28: Favorite Video Details | C28: =D28/$D$39*$F$4 -> 0.14025974 | D28: 3 | E28: =H28*4/I28 -> 0 | F28: =E28/4*C28 -> 0 | H28: 0 | I28: 3
B29: Favorite Video Redirect | C29: =D29/$D$39*$F$4 -> 0.046753247 | D29: 1 | E29: 0 | F29: =E29/4*C29 -> 0
B30: Like Tab Visibility | C30: =D30/$D$39*$F$4 -> 0.093506494 | D30: 2 | E30: 0 | F30: =E30/4*C30 -> 0
B31: Like Tab Content | C31: =D31/$D$39*$F$4 -> 0.093506494 | D31: 2 | E31: 4 | F31: =E31/4*C31 -> 0.093506494
B32: Like Video Tab Details | C32: =D32/$D$39*$F$4 -> 0.14025974 | D32: 3 | E32: =H32*4/I32 -> 2.6666667 | F32: =E32/4*C32 -> 0.093506494 | H32: 2 | I32: 3
B33: Like Video Redirect | C33: =D33/$D$39*$F$4 -> 0.046753247 | D33: 1 | E33: 4 | F33: =E33/4*C33 -> 0.046753247
B34: Private Account (Video and Details) | C34: =D34/$D$39*$F$4 -> 0.18701299 | D34: 4 | E34: 2 | F34: =E34/4*C34 -> 0.093506494
B35: Navigate Videos in Order | C35: =D35/$D$39*$F$4 -> 0.093506494 | D35: 2 | E35: 0 | F35: =E35/4*C35 -> 0
B36: Back to Video Just Watched (Profile Page) | C36: =D36/$D$39*$F$4 -> 0.37402597 | D36: 8 | E36: 0 | F36: =E36/4*C36 -> 0
B37: Cache Data for Backend | C37: =D37/$D$39*$F$4 -> 0.14025974 | D37: 3 | E37: 0 | F37: =E37/4*C37 -> 0
B38: Cache Data for Frontend | C38: =D38/$D$39*$F$4 -> 0.14025974 | D38: 3 | E38: 0 | F38: =E38/4*C38 -> 0
B39: Total | C39: =SUM(C6:C38) -> 3.6 | D39: =SUM(D6:D38) -> 77 | F39: =SUM(F6:F38) -> 1.7398887
B41: Page Design | C41: =Master!$D$12 -> 0.1 | F41: =C41*F2 -> 0.4
B42: Requirement | C42: Max | D42: Weight | E42: Score | F42: Harvested
B43: Aesthetic | C43: =D43/$D$48*$F$41 -> 0.08 | D43: 2 | E43: 4 | F43: =E43/4 * C43 -> 0.08
...

Sheet Create Playlist Page
B2: {=RIGHT(CELL("filename", A1), LEN(CELL("filename", A1)) - FIND("]", CELL("filename", A1)))} -> Create Playlist Page | F2: =VLOOKUP(B2,Master!B16:C38,2,FALSE) -> 2
B4: Page Features | C4: =Master!$D$11 -> 0.9 | F4: =C4*F2 -> 1.8
B5: Requirement | C5: Max | D5: Weight | E5: Score | F5: Harvested
B6: Display Components | C6: =D6/$D$17*$F$4 -> 0.06 | D6: 1 | E6: 2 | F6: =E6/4*C6 -> 0.03
B7: Back Button | C7: =D7/$D$17*$F$4 -> 0.06 | D7: 1 | E7: 4 | F7: =E7/4*C7 -> 0.06
B8: Input Playlist Name for Form | C8: =D8/$D$17*$F$4 -> 0.06 | D8: 1 | E8: 4 | F8: =E8/4*C8 -> 0.06
B9: Add Video to Playlist | C9: =D9/$D$17*$F$4 -> 0.18 | D9: 3 | E9: 4 | F9: =E9/4*C9 -> 0.18
B10: Remove Video to Playlist | C10: =D10/$D$17*$F$4 -> 0.18 | D10: 3 | E10: 4 | F10: =E10/4*C10 -> 0.18
B11: Reorder Video | C11: =D11/$D$17*$F$4 -> 0.3 | D11: 5 | E11: 4 | F11: =E11/4*C11 -> 0.3
B12: Drag and Drop to Reorder | C12: =D12/$D$17*$F$4 -> 0.3 | D12: 5 | E12: 4 | F12: =E12/4*C12 -> 0.3
B13: Validate Public Post Only | C13: =D13/$D$17*$F$4 -> 0.12 | D13: 2 | E13: 4 | F13: =E13/4*C13 -> 0.12
B14: Submit Logic | C14: =D14/$D$17*$F$4 -> 0.24 | D14: 4 | E14: 4 | F14: =E14/4*C14 -> 0.24
B15: Error Message | C15: =D15/$D$17*$F$4 -> 0.18 | D15: 3 | E15: 3 | F15: =E15/4*C15 -> 0.135
B16: Redirect to Login Page if Unauthorized | C16: =D16/$D$17*$F$4 -> 0.12 | D16: 2 | E16: 4 | F16: =E16/4*C16 -> 0.12
B17: Total | C17: =SUM(C6:C16) -> 1.8 | D17: =SUM(D6:D16) -> 30 | F17: =SUM(F6:F16) -> 1.725
B19: Page Design | C19: =Master!$D$12 -> 0.1 | F19: =C19*F2 -> 0.2
B20: Requirement | C20: Max | D20: Weight | E20: Score | F20: Harvested
B21: Aesthetic | C21: =D21/$D$25*$F$19 -> 0.057142857 | D21: 2 | E21: 3 | F21: =E21/4 * C21 -> 0.042857143
B22: Accessibility | C22: =D22/$D$25*$F$19 -> 0.085714286 | D22: 3 | E22: 3 | F22: =E22/4 * C22 -> 0.064285714
B23: Rounded Consistency | C23: =D23/$D$25*$F$19 -> 0.028571429 | D23: 1 | E23: 3 | F23: =E23/4 * C23 -> 0.021428571
B24: Padding | C24: =D24/$D$25*$F$19 -> 0.028571429 | D24: 1 | E24: 3 | F24: =E24/4 * C24 -> 0.021428571
B25: Total | C25: =SUM(C21:C24) -> 0.2 | D25: =SUM(D21:D24) -> 7 | F25: =SUM(F21:F24) -> 0.15
B27: Grand Total | F27: =SUM(F17,F25) -> 1.875

Sheet Search Page
B2: {=RIGHT(CELL("filename", A1), LEN(CELL("filename", A1)) - FIND("]", CELL("filename", A1)))} -> Search Page | F2: =VLOOKUP(B2,Master!B16:C38,2,FALSE) -> 3
B4: Page Features | C4: =Master!$D$11 -> 0.9 | F4: =C4*F2 -> 2.7
B5: Requirement | C5: Max | D5: Weight | E5: Score | F5: Harvested
B6: Display Components | C6: =D6/$D$19*$F$4 -> 0.038571429 | D6: 1 | E6: 4 | F6: =E6/4*C6 -> 0.038571429
B7: Debounce Search | C7: =D7/$D$19*$F$4 -> 0.19285714 | D7: 5 | E7: 4 | F7: =E7/4*C7 -> 0.19285714
B8: Infinite Scrolling | C8: =D8/$D$19*$F$4 -> 0.27 | D8: 7 | E8: 0 | F8: =E8/4*C8 -> 0
B9: Loading Skeleton | C9: =D9/$D$19*$F$4 -> 0.27 | D9: 7 | E9: 4 | F9: =E9/4*C9 -> 0.27
B10: Explain Jaro Distance | C10: =D10/$D$19*$F$4 -> 0.38571429 | D10: 10 | E10: 2 | F10: =E10/4*C10 -> 0.19285714
B11: Jaro Distance | C11: =D11/$D$19*$F$4 -> 0.38571429 | D11: 10 | E11: 4 | F11: =E11/4*C11 -> 0.38571429
B12: Search Algorithm | C12: =D12/$D$19*$F$4 -> 0.46285714 | D12: 12 | E12: 2 | F12: =E12/4*C12 -> 0.23142857 | H12: Score Detail | I12: Total Detail
B13: User Card Details | C13: =D13/$D$19*$F$4 -> 0.19285714 | D13: 5 | E13: =H13*4/I13 -> 4.8 | F13: =E13/4*C13 -> 0.23142857 | H13: 12 | I13: 10
B14: Video Card Details | C14: =D14/$D$19*$F$4 -> 0.19285714 | D14: 5 | E14: =H14*4/I14 -> 3.5555556 | F14: =E14/4*C14 -> 0.17142857 | H14: 8 | I14: 9
B15: Video Card Redirect | C15: =D15/$D$19*$F$4 -> 0.038571429 | D15: 1 | E15: 3 | F15: =E15/4*C15 -> 0.028928571
B16: User Card Redirect | C16: =D16/$D$19*$F$4 -> 0.038571429 | D16: 1 | E16: 4 | F16: =E16/4*C16 -> 0.038571429
B17: Cache Data for Backend | C17: =D17/$D$19*$F$4 -> 0.11571429 | D17: 3 | E17: 0 | F17: =E17/4*C17 -> 0
B18: Cache Data for Frontend | C18: =D18/$D$19*$F$4 -> 0.11571429 | D18: 3 | E18: 0 | F18: =E18/4*C18 -> 0
B19: Total | C19: =SUM(C6:C18) -> 2.7 | D19: =SUM(D6:D18) -> 70 | F19: =SUM(F6:F18) -> 1.7817857
B21: Page Design | C21: =Master!$D$12 -> 0.1 | F21: =C21*F2 -> 0.3
B22: Requirement | C22: Max | D22: Weight | E22: Score | F22: Harvested
B23: Aesthetic | C23: =D23/$D$28*$F$21 -> 0.045 | D23: 15 | E23: 3 | F23: =E23/4 * C23 -> 0.03375
B24: Error Message | C24: =D24/$D$28*$F$21 -> 0.03 | D24: 10 | E24: 3 | F24: =E24/4 * C24 -> 0.0225
B25: Accessibility | C25: =D25/$D$28*$F$21 -> 0.045 | D25: 15 | E25: 3 | F25: =E25/4 * C25 -> 0.03375
B26: Rounded Consistency | C26: =D26/$D$28*$F$21 -> 0.09 | D26: 30 | E26: 3 | F26: =E26/4 * C26 -> 0.0675
B27: Padding | C27: =D27/$D$28*$F$21 -> 0.09 | D27: 30 | E27: 3 | F27: =E27/4 * C27 -> 0.0675
B28: Total | C28: =SUM(C23:C27) -> 0.3 | D28: =SUM(D23:D27) -> 100 | F28: =SUM(F23:F27) -> 0.225
B30: Grand Total | F30: =SUM(,F19,F28) -> 2.0067857

Sheet Rich Text
B2: {=RIGHT(CELL("filename", A1), LEN(CELL("filename", A1)) - FIND("]", CELL("filename", A1)))} -> Rich Text | F2: =VLOOKUP(B2,Master!B16:C38,2,FALSE) -> 1
B3: Requirement | C3: Max | D3: Weight | E3: Score | F3: Harvested
B4: User Mentions (Bold) | C4: =D4/$D$10*$F$2 -> 0.16666667 | D4: 1 | E4: 4 | F4: =E4/4*C4 -> 0.16666667
B5: User Mentions (Redirect) | C5: =D5/$D$10*$F$2 -> 0.16666667 | D5: 1 | E5: 4 | F5: =E5/4*C5 -> 0.16666667
B6: Hash Tag (Bold) | C6: =D6/$D$10*$F$2 -> 0.16666667 | D6: 1 | E6: 4 | F6: =E6/4*C6 -> 0.16666667
B7: Hash Tag (Redirect) | C7: =D7/$D$10*$F$2 -> 0.16666667 | D7: 1 | E7: 4 | F7: =E7/4*C7 -> 0.16666667
B8: Hash Tag (Validation) | C8: =D8/$D$10*$F$2 -> 0.16666667 | D8: 1 | E8: 0 | F8: =E8/4*C8 -> 0
B9: Mention (Validation) | C9: =D9/$D$10*$F$2 -> 0.16666667 | D9: 1 | E9: 4 | F9: =E9/4*C9 -> 0.16666667
B10: Total | C10: =SUM(C4:C9) -> 1 | D10: =SUM(D4:D9) -> 6 | F10: =SUM(F4:F9) -> 0.83333333

Sheet Settings Page
B2: {=RIGHT(CELL("filename", A1), LEN(CELL("filename", A1)) - FIND("]", CELL("filename", A1)))} -> Settings Page | F2: =VLOOKUP(B2,Master!B16:C38,2,FALSE) -> 4
B4: Page Features | C4: =Master!$D$11 -> 0.9 | F4: =C4*F2 -> 3.6
B5: Requirement | C5: Max | D5: Weight | E5: Score | F5: Harvested
B6: Redirect to Login Page if Unauthorized | C6: =D6/$D$18*$F$4 -> 0.12413793 | D6: 2 | E6: 4 | F6: =E6/4*C6 -> 0.12413793
B7: Back Button | C7: =D7/$D$18*$F$4 -> 0.062068966 | D7: 1 | E7: 4 | F7: =E7/4*C7 -> 0.062068966
B8: Enable / Disable Notification (New Follower) | C8: =D8/$D$18*$F$4 -> 0.62068966 | D8: 10 | E8: 0 | F8: =E8/4*C8 -> 0
B9: Enable / Disable Notification (Message) | C9: =D9/$D$18*$F$4 -> 0.62068966 | D9: 10 | E9: 0 | F9: =E9/4*C9 -> 0
B10: Enable / Disable Notification (Mentions) | C10: =D10/$D$18*$F$4 -> 0.62068966 | D10: 10 | E10: 0 | F10: =E10/4*C10 -> 0
B11: Like Tab Visibility | C11: =D11/$D$18*$F$4 -> 0.24827586 | D11: 4 | E11: 2 | F11: =E11/4*C11 -> 0.12413793
B12: Account Content Privacy | C12: =D12/$D$18*$F$4 -> 0.24827586 | D12: 4 | E12: 4 | F12: =E12/4*C12 -> 0.24827586
B13: Chat Restriction Setting | C13: =D13/$D$18*$F$4 -> 0.24827586 | D13: 4 | E13: 0 | F13: =E13/4*C13 -> 0
B14: Delete Account Permanently | C14: =D14/$D$18*$F$4 -> 0.37241379 | D14: 6 | E14: 4 | F14: =E14/4*C14 -> 0.37241379
B15: Reset Password Page (Link) | C15: =D15/$D$18*$F$4 -> 0.062068966 | D15: 1 | E15: 4 | F15: =E15/4*C15 -> 0.062068966
B16: Cache Data for Backend | C16: =D16/$D$18*$F$4 -> 0.1862069 | D16: 3 | E16: 0 | F16: =E16/4*C16 -> 0
B17: Cache Data for Frontend | C17: =D17/$D$18*$F$4 -> 0.1862069 | D17: 3 | E17: 0 | F17: =E17/4*C17 -> 0
B18: Total | C18: =SUM(C6:C17) -> 3.6 | D18: =SUM(D6:D17) -> 58 | F18: =SUM(F6:F15) -> 0.99310345
B20: Page Design | C20: =Master!$D$12 -> 0.1 | F20: =C20*F2 -> 0.4
B21: Requirement | C21: Max | D21: Weight | E21: Score | F21: Harvested
B22: Aesthetic | C22: =D22/$D$27*$F$20 -> 0.05 | D22: 15 | E22: 3 | F22: =E22/4 * C22 -> 0.0375
B23: Error Message | C23: =D23/$D$27*$F$20 -> 0.1 | D23: 30 | E23: 3 | F23: =E23/4 * C23 -> 0.075
B24: Accessibility | C24: =D24/$D$27*$F$20 -> 0.05 | D24: 15 | E24: 3 | F24: =E24/4 * C24 -> 0.0375
B25: Rounded Consistency | C25: =D25/$D$27*$F$20 -> 0.1 | D25: 30 | E25: 3 | F25: =E25/4 * C25 -> 0.075
B26: Padding | C26: =D26/$D$27*$F$20 -> 0.1 | D26: 30 | E26: 3 | F26: =E26/4 * C26 -> 0.075
B27: Total | C27: =SUM(C22:C26) -> 0.4 | D27: =SUM(D22:D26) -> 120 | F27: =SUM(F22:F26) -> 0.3
B29: Grand Total | F29: =SUM(,F18,F27) -> 1.2931034

Sheet Advertisement
B2: {=RIGHT(CELL("filename", A12), LEN(CELL("filename", A12)) - FIND("]", CELL("filename", A12)))} -> Advertisement | F2: =VLOOKUP(B2,Master!B27:C49,2,FALSE) -> 1
B3: Requirement | C3: Max | D3: Weight | E3: Score | F3: Harvested
B4: Play random advertisement every n times | C4: =D4/$D$6*$F$2 -> 0.28571429 | D4: 4 | E4: 4 | F4: =E4/4*C4 -> 0.28571429
B5: Don't save Video Count in Database | C5: =D5/$D$6*$F$2 -> 0.71428571 | D5: 10 | E5: 4 | F5: =E5/4*C5 -> 0.71428571
B6: Total | C6: =SUM(C4:C5) -> 1 | D6: =SUM(D4:D5) -> 14 | F6: =SUM(F4:F5) -> 1

Sheet Studio Upload Page
B2: {=RIGHT(CELL("filename", A1), LEN(CELL("filename", A1)) - FIND("]", CELL("filename", A1)))} -> Studio Upload Page | F2: =VLOOKUP(B2,Master!B16:C38,2,FALSE) -> 5
B4: Page Features | C4: =Master!$D$11 -> 0.9 | F4: =C4*F2 -> 4.5
B5: Requirement | C5: Max | D5: Weight | E5: Score | F5: Harvested
B6: Display Components | C6: =D6/$D$20*$F$4 -> 0.0625 | D6: 1 | E6: 4 | F6: =E6/4*C6 -> 0.0625
B7: Redirect to Login Page if Unauthorized | C7: =D7/$D$20*$F$4 -> 0.0625 | D7: 1 | E7: 4 | F7: =E7/4*C7 -> 0.0625
B8: Upload Video with MinIO | C8: =D8/$D$20*$F$4 -> 0.625 | D8: 10 | E8: 4 | F8: =E8/4*C8 -> 0.625
B9: Display Progress Bar (Now MB/Max MB) | C9: =D9/$D$20*$F$4 -> 0.625 | D9: 10 | E9: 0 | F9: =E9/4*C9 -> 0
B10: Display Duration | C10: =D10/$D$20*$F$4 -> 0.625 | D10: 10 | E10: 4 | F10: =E10/4*C10 -> 0.625
B11: Add Description with Rich Text | C11: =D11/$D$20*$F$4 -> 0.125 | D11: 2 | E11: 4 | F11: =E11/4*C11 -> 0.125
B12: Select or Upload Thumbnail | C12: =D12/$D$20*$F$4 -> 0.5 | D12: 8 | E12: 4 | F12: =E12/4*C12 -> 0.5
B13: Can Enable/Disable Comments | C13: =D13/$D$20*$F$4 -> 0.3125 | D13: 5 | E13: 4 | F13: =E13/4*C13 -> 0.3125
B14: Can Set Video Visibility | C14: =D14/$D$20*$F$4 -> 0.1875 | D14: 3 | E14: 1 | F14: =E14/4*C14 -> 0.046875
B15: Schedule Video to be Posted | C15: =D15/$D$20*$F$4 -> 0.3125 | D15: 5 | E15: 0 | F15: =E15/4*C15 -> 0
B16: Add Video to Playlist | C16: =D16/$D$20*$F$4 -> 0.3125 | D16: 5 | E16: 2 | F16: =E16/4*C16 -> 0.15625
B17: Save Video as Draft | C17: =D17/$D$20*$F$4 -> 0.3125 | D17: 5 | E17: 4 | F17: =E17/4*C17 -> 0.3125
... B19: Posting Logic | C19: =D19/$D$20*$F$4 -> 0.375 | D19: 6 | E19: 4 | F19: =E19/4*C19 -> 0.375
B20: Total | C20: =SUM(C6:C19) -> 4.5 | D20: =SUM(D6:D19) -> 72 | F20: =SUM(F6:F19) -> 3.203125
B22: Page Design | C22: =Master!$D$12 -> 0.1 | F22: =C22*F2 -> 0.5
B23: Requirement | C23: Max | D23: Weight | E23: Score | F23: Harvested
B24: Aesthetic | C24: =D24/$D$29*$F$22 -> 0.1 | D24: 2 | E24: 3 | F24: =E24/4 * C24 -> 0.075
B25: Accessibility | C25: =D25/$D$29*$F$22 -> 0.15 | D25: 3 | E25: 3 | F25: =E25/4 * C25 -> 0.1125
B26: Error Message | C26: =D26/$D$29*$F$22 -> 0.15 | D26: 3 | E26: 3 | F26: =E26/4 * C26 -> 0.1125
B27: Rounded Consistency | C27: =D27/$D$29*$F$22 -> 0.05 | D27: 1 | E27: 3 | F27: =E27/4 * C27 -> 0.0375
B28: Padding | C28: =D28/$D$29*$F$22 -> 0.05 | D28: 1 | E28: 3 | F28: =E28/4 * C28 -> 0.0375
B29: Total | C29: =SUM(C24:C28) -> 0.5 | D29: =SUM(D24:D28) -> 10 | F29: =SUM(F24:F28) -> 0.375
B31: Grand Total | F31: =SUM(F20,F29) -> 3.578125

Sheet Studio Post Page
B2: {=RIGHT(CELL("filename", A1), LEN(CELL("filename", A1)) - FIND("]", CELL("filename", A1)))} -> Studio Post Page | F2: =VLOOKUP(B2,Master!B16:C38,2,FALSE) -> 4
B4: Page Features | C4: =Master!$D$11 -> 0.9 | F4: =C4*F2 -> 3.6
B5: Requirement | C5: Max | D5: Weight | E5: Score | F5: Harvested
B6: Display Components | C6: =D6/$D$26*$F$4 -> 0.043902439 | D6: 1 | E6: 4 | F6: =E6/4*C6 -> 0.043902439
B7: Redirect to Login Page if Unauthorized | C7: =D7/$D$26*$F$4 -> 0.043902439 | D7: 1 | E7: 4 | F7: =E7/4*C7 -> 0.043902439
B8: Display Published Posts | C8: =D8/$D$26*$F$4 -> 0.13170732 | D8: 3 | E8: 4 | F8: =E8/4*C8 -> 0.13170732 | H8: Score Detail | I8: Total Detail
B9: Display Published Video Details | C9: =D9/$D$26*$F$4 -> 0.2195122 | D9: 5 | E9: =H9/I9*4 -> 3 | F9: =E9/4*C9 -> 0.16463415 | H9: 9 | I9: 12
B10: Display Drafted Videos | C10: =D10/$D$26*$F$4 -> 0.13170732 | D10: 3 | E10: 4 | F10: =E10/4*C10 -> 0.13170732
B11: Display Draft Video Details | C11: =D11/$D$26*$F$4 -> 0.2195122 | D11: 5 | E11: =H11/I11*4 -> 3.3333333 | F11: =E11/4*C11 -> 0.18292683 | H11: 5 | I11: 6
B12: Edit Post | C12: =D12/$D$26*$F$4 -> 0.43902439 | D12: 10 | E12: 2 | F12: =E12/4*C12 -> 0.2195122
B13: Edit Draft | C13: =D13/$D$26*$F$4 -> 0.43902439 | D13: 10 | E13: 2 | F13: =E13/4*C13 -> 0.2195122
B14: Delete Post | C14: =D14/$D$26*$F$4 -> 0.26341463 | D14: 6 | E14: 2 | F14: =E14/4*C14 -> 0.13170732
B15: Delete Draft | C15: =D15/$D$26*$F$4 -> 0.26341463 | D15: 6 | E15: 2 | F15: =E15/4*C15 -> 0.13170732
B16: Sort Post By Like (Ascending) | C16: =D16/$D$26*$F$4 -> 0.13170732 | D16: 3 | E16: 4 | F16: =E16/4*C16 -> 0.13170732
B17: Sort Post By Like (Descending) | C17: =D17/$D$26*$F$4 -> 0.13170732 | D17: 3 | E17: 4 | F17: =E17/4*C17 -> 0.13170732
B18: Sort Post By View (Ascending) | C18: =D18/$D$26*$F$4 -> 0.13170732 | D18: 3 | E18: 0 | F18: =E18/4*C18 -> 0
B19: Sort Post By View (Descending) | C19: =D19/$D$26*$F$4 -> 0.13170732 | D19: 3 | E19: 0 | F19: =E19/4*C19 -> 0
B20: Sort Post By Comments (Ascending) | C20: =D20/$D$26*$F$4 -> 0.13170732 | D20: 3 | E20: 4 | F20: =E20/4*C20 -> 0.13170732
B21: Sort Post By Comments (Descending) | C21: =D21/$D$26*$F$4 -> 0.13170732 | D21: 3 | E21: 4 | F21: =E21/4*C21 -> 0.13170732
B22: Search by Description | C22: =D22/$D$26*$F$4 -> 0.087804878 | D22: 2 | E22: 4 | F22: =E22/4*C22 -> 0.087804878
B23: Debounce Search | C23: =D23/$D$26*$F$4 -> 0.26341463 | D23: 6 | E23: 4 | F23: =E23/4*C23 -> 0.26341463
... B25: Cache Data for Frontend | C25: =D25/$D$26*$F$4 -> 0.13170732 | D25: 3 | E25: 0 | F25: =E25/4*C25 -> 0
B26: Total | C26: =SUM(C6:C25) -> 3.6 | D26: =SUM(D6:D25) -> 82 | F26: =SUM(F6:F25) -> 2.2792683
B28: Page Design | C28: =Master!$D$12 -> 0.1 | F28: =C28*F2 -> 0.4
B29: Requirement | C29: Max | D29: Weight | E29: Score | F29: Harvested
B30: Aesthetic | C30: =D30/$D$35*$F$28 -> 0.06 | D30: 15 | E30: 3 | F30: =E30/4 * C30 -> 0.045
B31: Error Message | C31: =D31/$D$35*$F$28 -> 0.04 | D31: 10 | E31: 3 | F31: =E31/4 * C31 -> 0.03
B32: Accessibility | C32: =D32/$D$35*$F$28 -> 0.06 | D32: 15 | E32: 3 | F32: =E32/4 * C32 -> 0.045
B33: Rounded Consistency | C33: =D33/$D$35*$F$28 -> 0.12 | D33: 30 | E33: 3 | F33: =E33/4 * C33 -> 0.09
B34: Padding | C34: =D34/$D$35*$F$28 -> 0.12 | D34: 30 | E34: 3 | F34: =E34/4 * C34 -> 0.09
B35: Total | C35: =SUM(C30:C34) -> 0.4 | D35: =SUM(D30:D34) -> 100 | F35: =SUM(F30:F34) -> 0.3
B37: Grand Total | F37: =SUM(,F26,F35) -> 2.5792683

Sheet Chat Page
B2: {=RIGHT(CELL("filename", A1), LEN(CELL("filename", A1)) - FIND("]", CELL("filename", A1)))} -> Chat Page | F2: =VLOOKUP(B2,Master!B16:C38,2,FALSE) -> 7
B4: Page Features | C4: =Master!$D$11 -> 0.9 | F4: =C4*F2 -> 6.3
B5: Requirement | C5: Max | D5: Weight | E5: Score | F5: Harvested
B6: Display Components | C6: =D6/$D$34*$F$4 -> 0.045323741 | D6: 1 | E6: 4 | F6: =E6/4*C6 -> 0.045323741
B7: Real-time Chat | C7: =D7/$D$34*$F$4 -> 1.3597122 | D7: 30 | E7: 4 | F7: =E7/4*C7 -> 1.3597122
B8: User Send Message | C8: =D8/$D$34*$F$4 -> 0.22661871 | D8: 5 | E8: 4 | F8: =E8/4*C8 -> 0.22661871 | H8: Score Detail | I8: Total Detail
B9: Notification Detail | C9: =D9/$D$34*$F$4 -> 0.36258993 | D9: 8 | E9: =H9/I9*4 -> 0 | F9: =E9/4*C9 -> 0 | H9: 0 | I9: 4
B10: Notification Web | C10: =D10/$D$34*$F$4 -> 0.22661871 | D10: 5 | E10: 0 | F10: =E10/4*C10 -> 0
B11: Restriction Chat | C11: =D11/$D$34*$F$4 -> 0.36258993 | D11: 8 | E11: 0 | F11: =E11/4*C11 -> 0
B12: Redirect to Login Page if Unauthorized | C12: =D12/$D$34*$F$4 -> 0.045323741 | D12: 1 | E12: 4 | F12: =E12/4*C12 -> 0.045323741
B13: Message List
B14: Display List of Conversations | C14: =D14/$D$34*$F$4 -> 0.13597122 | D14: 3 | E14: =H14/I14*4 -> 2 | F14: =E14/4*C14 -> 0.067985612 | H14: 2 | I14: 4
B15: Open Chat Window (When clicking conversation) | C15: =D15/$D$34*$F$4 -> 0.090647482 | D15: 2 | E15: 4 | F15: =E15/4*C15 -> 0.090647482
B16: Search by Username | C16: =D16/$D$34*$F$4 -> 0.18129496 | D16: 4 | E16: 4 | F16: =E16/4*C16 -> 0.18129496
B17: Debounce Search | C17: =D17/$D$34*$F$4 -> 0.18129496 | D17: 4 | E17: 3 | F17: =E17/4*C17 -> 0.13597122
B18: Infinite Scrolling (Message List) | C18: =D18/$D$34*$F$4 -> 0.18129496 | D18: 4 | E18: 3 | F18: =E18/4*C18 -> 0.13597122
B19: Loading Skeleton (Message List) | C19: =D19/$D$34*$F$4 -> 0.18129496 | D19: 4 | E19: 3 | F19: =E19/4*C19 -> 0.13597122
B20: Chat Window
B21: Infinite Scrolling (Chat Window) | C21: =D21/$D$34*$F$4 -> 0.18129496 | D21: 4 | E21: 0 | F21: =E21/4*C21 -> 0
B22: Loading Skeleton (Chat Window) | C22: =D22/$D$34*$F$4 -> 0.18129496 | D22: 4 | E22: 0 | F22: =E22/4*C22 -> 0
B23: Send Text | C23: =D23/$D$34*$F$4 -> 0.13597122 | D23: 3 | E23: 4 | F23: =E23/4*C23 -> 0.13597122
B24: Send Image | C24: =D24/$D$34*$F$4 -> 0.22661871 | D24: 5 | E24: 4 | F24: =E24/4*C24 -> 0.22661871
B25: Send Video | C25: =D25/$D$34*$F$4 -> 0.22661871 | D25: 5 | E25: 0 | F25: =E25/4*C25 -> 0
B26: Display Chat Window Detail | C26: =D26/$D$34*$F$4 -> 0.13597122 | D26: 3 | E26: =H26/I26*4 -> 4 | F26: =E26/4*C26 -> 0.13597122 | H26: 3 | I26: 3
B27: Tiktok Video Share | C27: =D27/$D$34*$F$4 -> 0.36258993 | D27: 8 | E27: 0 | F27: =E27/4*C27 -> 0
B28: Tiktok Video Share Redirect | C28: =D28/$D$34*$F$4 -> 0.090647482 | D28: 2 | E28: 0 | F28: =E28/4*C28 -> 0
B29: Chat Message Detail | C29: =D29/$D$34*$F$4 -> 0.22661871 | D29: 5 | E29: =H29/I29*4 -> 1.6 | F29: =E29/4*C29 -> 0.090647482 | H29: 2 | I29: 5
B30: User Unsend Message | C30: =D30/$D$34*$F$4 -> 0.22661871 | D30: 5 | E30: 4 | F30: =E30/4*C30 -> 0.22661871
B31: Display User Currently Typing | C31: =D31/$D$34*$F$4 -> 0.45323741 | D31: 10 | E31: 4 | F31: =E31/4*C31 -> 0.45323741
B32: Cache Data for Backend | C32: =D32/$D$34*$F$4 -> 0.13597122 | D32: 3 | E32: 0 | F32: =E32/4*C32 -> 0
B33: Cache Data for Frontend | C33: =D33/$D$34*$F$4 -> 0.13597122 | D33: 3 | E33: 0 | F33: =E33/4*C33 -> 0
B34: Total | C34: =SUM(C6:C33) -> 6.3 | D34: =SUM(D6:D33) -> 139 | F34: =SUM(F6:F33) -> 3.6938849
B36: Page Design | C36: =Master!$D$12 -> 0.1 | F36: =C36*F2 -> 0.7
B37: Requirement | C37: Max | D37: Weight | E37: Score | F37: Harvested
B38: Aesthetic | C38: =D38/$D$43*$F$36 -> 0.0875 | D38: 15 | E38: 3 | F38: =E38/4 * C38 -> 0.065625
B39: Error Message | C39: =D39/$D$43*$F$36 -> 0.175 | D39: 30 | E39: 3 | F39: =E39/4 * C39 -> 0.13125
B40: Accessibility | C40: =D40/$D$43*$F$36 -> 0.0875 | D40: 15 | E40: 3 | F40: =E40/4 * C40 -> 0.065625
B41: Rounded Consistency | C41: =D41/$D$43*$F$36 -> 0.175 | D41: 30 | E41: 3 | F41: =E41/4 * C41 -> 0.13125
B42: Padding | C42: =D42/$D$43*$F$36 -> 0.175 | D42: 30 | E42: 3 | F42: =E42/4 * C42 -> 0.13125
B43: Total | C43: =SUM(C38:C42) -> 0.7 | D43: =SUM(D38:D42) -> 120 | F43: =SUM(F38:F42) -> 0.525
...

Sheet Live
B2: {=RIGHT(CELL("filename", A1), LEN(CELL("filename", A1)) - FIND("]", CELL("filename", A1)))} -> Live | F2: =VLOOKUP(B2,Master!B16:C38,2,FALSE) -> 5
B4: Page Features | C4: =Master!$D$11 -> 0.9 | F4: =C4*F2 -> 4.5
B5: Requirement | C5: Max | D5: Weight | E5: Score | F5: Harvested
B6: Live Page
B7: Display Components | C7: =D7/$D$37*$F$4 -> 0.017110266 | D7: 1 | E7: 4 | F7: =E7/4*C7 -> 0.017110266
B8: Redirect to Login Page if Unauthorized | C8: =D8/$D$37*$F$4 -> 0.017110266 | D8: 1 | E8: 4 | F8: =E8/4*C8 -> 0.017110266
B9: Display Active Live Streams List | C9: =D9/$D$37*$F$4 -> 0.051330798 | D9: 3 | E9: 0 | F9: =E9/4*C9 -> 0 | H9: Score Detail | I9: Total Detail
B10: Display List Details | C10: =D10/$D$37*$F$4 -> 0.051330798 | D10: 3 | E10: =H10/I10*4 -> 0 | F10: =E10/4*C10 -> 0 | H10: 0 | I10: 9
B11: Redirect when Joining Stream | C11: =D11/$D$37*$F$4 -> 0.017110266 | D11: 1 | E11: 0 | F11: =E11/4*C11 -> 0
B12: Live Stream Detail
B13: Explain Streaming | C13: =D13/$D$37*$F$4 -> 0.51330798 | D13: 30 | E13: 0 | F13: =E13/4*C13 -> 0
B14: Display Live Stream Details | C14: =D14/$D$37*$F$4 -> 0.068441065 | D14: 4 | E14: =H14/I14*4 -> 1.6 | F14: =E14/4*C14 -> 0.027376426 | H14: 2 | I14: 5
B15: Live Video Stream | C15: =D15/$D$37*$F$4 -> 0.51330798 | D15: 30 | E15: 0 | F15: =E15/4*C15 -> 0
B16: Display Total Like (Real-time) | C16: =D16/$D$37*$F$4 -> 0.20532319 | D16: 12 | E16: 2 | F16: =E16/4*C16 -> 0.1026616
B17: Display Number of People Join (Real-time) | C17: =D17/$D$37*$F$4 -> 0.068441065 | D17: 4 | E17: 2 | F17: =E17/4*C17 -> 0.034220532
B18: Display Live Duration (Real-time) | C18: =D18/$D$37*$F$4 -> 0.13688213 | D18: 8 | E18: 0 | F18: =E18/4*C18 -> 0
B19: Show Streamer Screen | C19: =D19/$D$37*$F$4 -> 0.51330798 | D19: 30 | E19: 3 | F19: =E19/4*C19 -> 0.38498099
B20: Show Streamer Camera | C20: =D20/$D$37*$F$4 -> 0.51330798 | D20: 30 | E20: 3 | F20: =E20/4*C20 -> 0.38498099
B21: Display Chat (Real-time) | C21: =D21/$D$37*$F$4 -> 0.34220532 | D21: 20 | E21: 3 | F21: =E21/4*C21 -> 0.25665399 | H21: 2 | I21: 8
B22: Display Chat Detail | C22: =D22/$D$37*$F$4 -> 0.068441065 | D22: 4 | E22: =H21/I21*4 -> 1 | F22: =E22/4*C22 -> 0.017110266
B23: Send Message to Chat | C23: =D23/$D$37*$F$4 -> 0.13688213 | D23: 8 | E23: 3 | F23: =E23/4*C23 -> 0.1026616
B24: Join Notification | C24: =D24/$D$37*$F$4 -> 0.25665399 | D24: 15 | E24: 2 | F24: =E24/4*C24 -> 0.128327
B25: Like Stream | C25: =D25/$D$37*$F$4 -> 0.068441065 | D25: 4 | E25: 2 | F25: =E25/4*C25 -> 0.034220532
B26: Share Stream | C26: =D26/$D$37*$F$4 -> 0.034220532 | D26: 2 | E26: 0 | F26: =E26/4*C26 -> 0
B27: Live Stream Controls
B28: Start / Stop Live Stream | C28: =D28/$D$37*$F$4 -> 0.085551331 | D28: 5 | E28: 3 | F28: =E28/4*C28 -> 0.064163498
B29: Set or Edit Live Stream Title | C29: =D29/$D$37*$F$4 -> 0.017110266 | D29: 1 | E29: 0 | F29: =E29/4*C29 -> 0
B30: Number of People Join (Real-time) | C30: =D30/$D$37*$F$4 -> 0.034220532 | D30: 2 | E30: 2 | F30: =E30/4*C30 -> 0.017110266
B31: Total Like (Real-time) | C31: =D31/$D$37*$F$4 -> 0.20532319 | D31: 12 | E31: 2 | F31: =E31/4*C31 -> 0.1026616
B32: Live Duration (Real-time) | C32: =D32/$D$37*$F$4 -> 0.068441065 | D32: 4 | E32: 0 | F32: =E32/4*C32 -> 0
B33: Share Screen | C33: =D33/$D$37*$F$4 -> 0.25665399 | D33: 15 | E33: 3 | F33: =E33/4*C33 -> 0.19249049
B34: Enable / Disable Camera | C34: =D34/$D$37*$F$4 -> 0.13688213 | D34: 8 | E34: 3 | F34: =E34/4*C34 -> 0.1026616
B35: Cache Data for Backend | C35: =D35/$D$37*$F$4 -> 0.051330798 | D35: 3 | E35: 0 | F35: =E35/4*C35 -> 0
B36: Cache Data for Frontend | C36: =D36/$D$37*$F$4 -> 0.051330798 | D36: 3 | E36: 0 | F36: =E36/4*C36 -> 0
B37: Total | C37: =SUM(C7:C36) -> 4.5 | D37: =SUM(D7:D36) -> 263 | F37: =SUM(F7:F36) -> 1.9865019
B39: Page Design | C39: =Master!$D$12 -> 0.1 | F39: =C39*F2 -> 0.5
B40: Requirement | C40: Max | D40: Weight | E40: Score | F40: Harvested
B41: Aesthetic | C41: =D41/$D$45*$F$39 -> 0.083333333 | D41: 15 | E41: 3 | F41: =E41/4 * C41 -> 0.0625
B42: Accessibility | C42: =D42/$D$45*$F$39 -> 0.083333333 | D42: 15 | E42: 3 | F42: =E42/4 * C42 -> 0.0625
B43: Rounded Consistency | C43: =D43/$D$45*$F$39 -> 0.16666667 | D43: 30 | E43: 3 | F43: =E43/4 * C43 -> 0.125
...

Sheet AI Var 1 - SVilter
A1: =F10 -> 0
B2: {=RIGHT(CELL("filename", A1), LEN(CELL("filename", A1)) - FIND("]", CELL("filename", A1)))} -> AI Var 1 - SVilter | F2: =INDEX('AI Groups'!C3:G3,MATCH(B2,'AI Groups'!C2:G2)) -> 10
B3: Requirement | C3: Max | D3: Weight | E3: Score | F3: Harvested
B4: Dataset Preparation | C4: =D4/$D$10*$F$2 -> 0.22222222 | D4: 1 | E4: 0 | F4: =E4/4*C4 -> 0
B5: Filter | C5: =D5/$D$10*$F$2 -> 1.1111111 | D5: 5 | E5: 0 | F5: =E5/4*C5 -> 0
B6: Real-time Face Detection | C6: =D6/$D$10*$F$2 -> 2.2222222 | D6: 10 | E6: 0 | F6: =E6/4*C6 -> 0
B7: Filter Interactions | C7: =D7/$D$10*$F$2 -> 3.3333333 | D7: 15 | E7: 0 | F7: =E7/4*C7 -> 0
B8: Record Video with Filter | C8: =D8/$D$10*$F$2 -> 1.5555556 | D8: 7 | E8: 0 | F8: =E8/4*C8 -> 0
